Workbook
Name Excel_BuiltIn_Print_Area: NA()

Sheet Report
A1: CONTROLLO DI QUALITA' SU SISTEMI DIGITAL DIRECT RADIOGRAPHY
A2: ='Inserimento dati'!G3 -> DR tavolo
A4: Controllo del | C4: 45561
A6: Azienda: | C6: ASL TO 3 - P.O.Rivoli
A7: Sala/Unità operativa: | C7: Radiologia - Sala 1
A8: Unità: | C8: Telecomandato
A9: Ditta / Modello: | C9: Simeens Luminos dRF Max
A10: Numero di serie tubo: | C10: OPTITOP 150/40/80HC / SN 807262253
A11: Operatore: | C11: Cutaia, Pinna
A13: Note:
A17: Software analisi: | C17: imageJ
A19: Note:
A21: Condizioni di lavoro
A23: Protocollo di esame | B23: ='Inserimento dati'!G17 -> Fisica
A24: Griglia | B24: ='Inserimento dati'!H8 -> Assente
A25: Filtrazione aggiuntiva | B25: ='Inserimento dati'!D15 -> 1 mm Cu
A26: DFR | B26: cm | C26: ='Inserimento dati'!H5 -> 115
A27: Tensione | B27: kV | C27: ='Inserimento dati'!G20 -> 70
A30: Correnti di buio (DDR12 - Dark noise)
A32: Ogni giorno, all'accensione, l'apparecchiatura esegue un test automatico del noise (mappa).
A35: Funzione di conversione (Signal Transfer Property, STP)
A37: Karia al detettore desiderabile | B37: 1 - 2,5 - 5 - 10 - 20 - 30 µGy
A39: mAs set | B39: Karia (µGy) | C39: <PV> | D39: SD | E39: PV teorico | F39: EI
A40: ='Inserimento dati'!D25 -> 0.9 | B40: ='Inserimento dati'!C25 -> 1.017 | C40: ='Inserimento dati'!N31 -> 1179.573 | D40: ='Inserimento dati'!O31 -> 36.579 | E40: =IF($A$48="Logaritmica",$D$47*LN(B40)+$F$47,$D$47*(B40)+$F$47) -> 1165.1573 | F40: ='Inserimento dati'!C38 -> 52
A41: ='Inserimento dati'!D26 -> 2 | B41: ='Inserimento dati'!C26 -> 2.398 | C41: ='Inserimento dati'!N32 -> 2498.788 | D41: ='Inserimento dati'!O32 -> 55.679 | E41: =IF($A$48="Logaritmica",$D$47*LN(B41)+$F$47,$D$47*(B41)+$F$47) -> 2514.1713 | F41: ='Inserimento dati'!C39 -> 107
A42: ='Inserimento dati'!D27 -> 4 | B42: ='Inserimento dati'!C27 -> 5.039 | C42: ='Inserimento dati'!N33 -> 5091.01 | D42: ='Inserimento dati'!O33 -> 87.492 | E42: =IF($A$48="Logaritmica",$D$47*LN(B42)+$F$47,$D$47*(B42)+$F$47) -> 5094.0017 | F42: ='Inserimento dati'!C40 -> 214
A43: ='Inserimento dati'!D28 -> 8 | B43: ='Inserimento dati'!C28 -> 10.36 | C43: ='Inserimento dati'!N34 -> 10277.062 | D43: ='Inserimento dati'!O34 -> 144.639 | E43: =IF($A$48="Logaritmica",$D$47*LN(B43)+$F$47,$D$47*(B43)+$F$47) -> 10291.759 | F43: ='Inserimento dati'!C41 -> 421
A44: ='Inserimento dati'!D29 -> 16 | B44: ='Inserimento dati'!C29 -> 20.82 | C44: ='Inserimento dati'!N35 -> 20544.858 | D44: ='Inserimento dati'!O35 -> 250.989 | E44: =IF($A$48="Logaritmica",$D$47*LN(B44)+$F$47,$D$47*(B44)+$F$47) -> 20509.49 | F44: ='Inserimento dati'!C42 -> 835
A45: ='Inserimento dati'!D30 -> 25 | B45: ='Inserimento dati'!C30 -> 32.72 | C45: ='Inserimento dati'!N36 -> 32117.157 | D45: ='Inserimento dati'!O36 -> 360.49 | E45: =IF($A$48="Logaritmica",$D$47*LN(B45)+$F$47,$D$47*(B45)+$F$47) -> 32133.868 | F45: ='Inserimento dati'!C43 -> 1295
A47: Dipendenza PV da Karia | B47: Valori da grafico | C47: a= | D47: =IF(A48="LOG",'Inserimento dati'!D100,IF(Report!A48="LIN",'Inserimento dati'!D112,"ERRORE")) -> 976.8385 | E47: b= | F47: =IF(A48="LOG",'Inserimento dati'!E100,IF(Report!A48="LIN",'Inserimento dati'!E112,"ERRORE")) -> 171.71254
A48: ='Inserimento dati'!L14 -> LIN | B48: =IF(A48="LOG","y=a*ln(x)+b","y=a*x+b") -> y=a*x+b
A50: Dipendenza EI da Karia | B50: Valori da grafico | C50: c= | D50: =IF(A51="LOG",'Inserimento dati'!J100,IF(Report!A51="LIN",'Inserimento dati'!J112,"ERRORE")) -> 39.226481 | E50: d= | F50: =IF(A51="LOG",'Inserimento dati'!K100,IF(Report!A51="LIN",'Inserimento dati'!K112,"ERRORE")) -> 14.301195
A51: ='Inserimento dati'!O14 -> LIN | B51: =IF(A51="LOG","y=c*ln(x)+d","y=c*x+d") -> y=c*x+d
A91: Analisi delle componenti del rumore in funzione della dose (solo controllo di accettazione)
K92: RELAZIONE LINEARIZZATA
K93: Karia (µGy) | L93: ln(<K>) | M93: <PV> | N93: ln(<PV>)
A94: Karia (µGy) | B94: <PV> | C94: SD | D94: (SD2) | E94: ln(<K>) | F94: RSD2 | K94: =B40 -> 1.017 | L94: =LN(K94) -> 0.016857117 | M94: =C40 -> 1179.573 | N94: =LN(M94) -> 7.0729078
A95: =B40 -> 1.017 | B95: =C40 -> 1179.573 | C95: =D40 -> 36.579 | D95: =(C95^2) -> 1338.0232 | E95: =LN(D95) -> 7.1989486 | F95: =(C95/A95)^2 -> 1293.6648 | K95: =B41 -> 2.398 | L95: =LN(K95) -> 0.87463506 | M95: =C41 -> 2498.788 | N95: =LN(M95) -> 7.8235611
A96: =B41 -> 2.398 | B96: =C41 -> 2498.788 | C96: =D41 -> 55.679 | D96: =(C96^2) -> 3100.151 | E96: =LN(D96) -> 8.0392061 | F96: =(C96/A96)^2 -> 539.11882 | K96: =B42 -> 5.039 | L96: =LN(K96) -> 1.6172076 | M96: =C42 -> 5091.01 | N96: =LN(M96) -> 8.5352315
A97: =B42 -> 5.039 | B97: =C42 -> 5091.01 | C97: =D42 -> 87.492 | D97: =(C97^2) -> 7654.8501 | E97: =LN(D97) -> 8.9430947 | F97: =(C97/A97)^2 -> 301.47269 | K97: =B43 -> 10.36 | L97: =LN(K97) -> 2.3379522 | M97: =C43 -> 10277.062 | N97: =LN(M97) -> 9.2376697
...

Sheet Inserimento dati
B1: DA COMPILARE DURANTE IL CONTROLLO DEL DR | K1: DA COMPILARE DURANTE L'ANALISI DELLE IMMAGINI RAW
B3: Dove viene utilizzato il DR? | D3: (DR tavolo - DR Wall Stand - DR) | G3: DR tavolo | K3: Aprire il programma imageJ
B5: Se possibile lavorare con detettore fuori potter a distanza fuoco - detettore = | H5: 115 | I5: cm | K5: 1. RINOMINARE LE IMMAGINI
B7: Se non è possibile lavorare con detettore fuori potter: | K7: Selezionare Plugins e poi il programma "Rinomina File DR"
B8: ESTRARRE la GRIGLIA (ove è possibile) | E8: Griglia presente? (Assente/Presente) | H8: Assente
K9: Selezionare nella ricerca, la cartella contenente le immagini RAW scaricate dall'apparecchiatura
B10: LETTINO : distanza fuoco - detettore = 130 cm (se distanza diversa, indicarlo= | H10: 115 | I10: cm)
B11: STATIVO: Distanza fuoco – detettore = 180 cm (se distanza diversa indicarlo= | I11: cm) | K11: Verificare nel nome dei file se le immagini sono FOR PROCESSING (corretto) e scrivere qui sotto il tipo di curva
K12: (LOG o LIN)
N13: Scrivere LOG o LIN in base all'andamento dei dati del grafico di destra (grafico EI)
B14: Aggiungere filtro della ditta (in mancanza di filtro proprietario, inserire filtro 1 mm Cu) | K14: Tipo di curva | L14: LIN | N14: Tipo di curva EI | O14: LIN
B15: Tipo di filtro utilizzato e spessore: | D15: 1 mm Cu
K16: 2. ANALIZZARE LE IMMAGINI
B17: Riportare il protocollo scelto (meglio protocollo pattern o modello) | G17: Fisica
K18: a. Per visualizzare le immagini selezionare File, Import, Image Sequence, cliccare su un'immagine della
B19: Aprire i collimatori al massimo | K19: cartella e successivamente il tasto ok
B20: Condizioni di esposizione per ottenere su DR le seguenti dosi impostando | G20: 70 | H20: kV
B21: (meglio lavorare fuori potter, altrimenti escludere il detettore e coprirlo per evitare immagini di ghost) | K21: b. Per disegnare una Regione di Interesse (da qui in poi, chiamata ROI), cliccare sull'icona rettangolare
B22: Ricavare i mAs per ottenere dosi di ingresso pari a: | K22: in alto a sinistra della barra di ImageJ, poi tenendo premuto il taso sinistro del mouse disegnare una ROI
K23: di almeno 5 cm di lato e al centro dell'immagine
B24: uGy teorici | C24: mGy letti da Piranha | D24: mAs
B25: 1 | C25: 1.017 | D25: 0.9 | K25: Cliccare contemporaneamente i tasti CTRL e M: si apre una finestra con i valori di interesse
B26: 2.5 | C26: 2.398 | D26: 2 | K26: Ripetere il punto b. per le prime sei immagini (Funzione di risposta) e riportare i dati nella tabella sottostante
B27: 5 | C27: 5.039 | D27: 4 | K27: Excel: Dopo aver incollato i risultati, cliccare icona che compare in basso a destra della tabella → Usa importazione guidata testo, Avanti, Tabulazione, Avanti, Avanzate, scambiare punto e virgola, Ok, Fine
B28: 10 | C28: 10.36 | D28: 8 | K28: Libre Office: Modifica, Incolla speciale, Incolla testo non formattato → scegliere come Impostazioni locali: Inglese (USA) → OK
B29: 20 | C29: 20.82 | D29: 16 | K29: Funzione di risposta
B30: 30 | C30: 32.72 | D30: 25 | K30: Dosi (uGy) | L30: N immagine | M30: Area | N30: Media | O30: Dev.St. | P30: Min | Q30: Max
K31: =C25 -> 1.017 | L31: 1 | M31: 11045.924 | N31: 1179.573 | O31: 36.579 | P31: 992 | Q31: 1344
K32: =C26 -> 2.398 | L32: 2 | M32: 11045.924 | N32: 2498.788 | O32: 55.679 | P32: 2241 | Q32: 2769
B33: Acquisire le immagini di tutto il flat panel impostando i parametri precedenti (6 immagini uniformi): | K33: =C27 -> 5.039 | L33: 3 | M33: 11045.924 | N33: 5091.01 | O33: 87.492 | P33: 4705 | Q33: 5489
B34: campo aperto al max,togliere camice Pb se in uso per proteggere rivelatore.No Piranha. | K34: =C28 -> 10.36 | L34: 4 | M34: 11045.924 | N34: 10277.062 | O34: 144.639 | P34: 9634 | Q34: 10898
B35: Segnare il valore di EI | K35: =C29 -> 20.82 | L35: 5 | M35: 11045.924 | N35: 20544.858 | O35: 250.989 | P35: 19412 | Q35: 21605
K36: =C30 -> 32.72 | L36: 6 | M36: 11045.924 | N36: 32117.157 | O36: 360.49 | P36: 30471 | Q36: 33640
B37: uGy teorici | C37: EI | D37: =D24 -> mAs
B38: 1 | C38: 52 | D38: =D25 -> 0.9 | K38: e per la riproducibilità ripetere le misure sulle due immagini successive e inserirle nella tabella sottostante
B39: 2.5 | C39: 107 | D39: =D26 -> 2
B40: 5 | C40: 214 | D40: =D27 -> 4 | K40: Riproducibilità
B41: 10 | C41: 421 | D41: =D28 -> 8 | K41: Dosi (uGy) | L41: N immagine | M41: Area | N41: Media | O41: Dev.St. | P41: Min | Q41: Max
B42: 20 | C42: 835 | D42: =D29 -> 16 | K42: =K32 -> 2.398 | L42: =L32 -> 2 | M42: =M32 -> 11045.924 | N42: =N32 -> 2498.788 | O42: =O32 -> 55.679 | P42: =P32 -> 2241 | Q42: =Q32 -> 2769
B43: 30 | C43: 1295 | D43: =D30 -> 25 | K43: =K42 -> 2.398 | L43: 7 | M43: 11045.924 | N43: 2513.208 | O43: 55.658 | P43: 2225 | Q43: 2769
...

Sheet Riferimenti
A1: TOR CDR
A3: Disc Number | B3: Contrast | C3: High Contrast | D3: Resolution
A4: 1 | B4: 0.075 | C4: 0.954 | D4: 0.5
A5: 2 | B5: 0.067 | C5: 0.82 | D5: 0.56
A6: 3 | B6: 0.053 | C6: 0.726 | D6: 0.63
A7: 4 | B7: 0.045 | C7: 0.573 | D7: 0.71
A8: 5 | B8: 0.039 | C8: 0.496 | D8: 0.8
A9: 6 | B9: 0.032 | C9: 0.36 | D9: 0.9
A10: 7 | B10: 0.027 | C10: 0.302 | D10: 1
A11: 8 | B11: 0.022 | C11: 0.238 | D11: 1.12
A12: 9 | B12: 0.017 | C12: 0.203 | D12: 1.25
A13: 10 | B13: 0.015 | C13: 0.167 | D13: 1.4
A14: 11 | B14: 0.013 | C14: 0.128 | D14: 1.6
A15: 12 | B15: 0.011 | C15: 0.117 | D15: 1.8
... A20: 17 | B20: 0.002 | C20: 0.039 | D20: 3.15
A21: 18 | D21: 3.55
A22: 19 | D22: 4
A23: 20 | D23: 4.5
A24: 21 | D24: 5
A25: 22 | D25: 5.6
A26: 23 | D26: 6.3
A27: 24 | D27: 7.1
A28: 25 | D28: 8
A29: 26 | D29: 8.9
A30: 27 | D30: 10
A31: 28 | D31: 11.1
A32: 29 | D32: 12.5
A33: 30 | D33: 14.3
A38: Presente
A39: Assente
A41: Logaritmica
A42: Lineare
A44: DR Tavolo
A45: DR Wall Stand
A46: DR

Sheet per accettazione
A2: Acquisire TOR CDR a 20 uGy a 0° e 90° per ottenere la risoluzione spaziale max
A8: Precisione di misura di distanze e rapporto di formato (DDR11 – Scaling errors)
A10: Tensione | B10: (kV) | C10: =+'per accettazione'!C31 -> 50
A11: DFR | B11: (cm) | C11: 130
A12: DF-Tool | B12: (cm) | C12: 125
A13: Griglia | B13: assente
A14: Fantoccio: | B14: ETR
A15: Scala | C15: =C11/C12 -> 1.04
B17: Dim. ImageJ (mm) | C17: Dim. ETR (mm) | D17: Dim. mm reale | E17: Diff. % | F17: Toll. | G17: Acc.
A18: I quadrante | B18: 10.5 | C18: 10 | D18: =B18/$C$15 -> 10.096154 | E18: =ABS((C18-D18)/(D18)) -> 0.0095238095 | F18: < 2% | G18: < 4%
A19: II quadrante | B19: 10.567 | C19: 10 | D19: =B19/$C$15 -> 10.160577 | E19: =ABS((C19-D19)/(D19)) -> 0.015803918 | F19: < 2% | G19: < 4%
A20: III quadrante | B20: 10.603 | C20: 10 | D20: =B20/$C$15 -> 10.195192 | E20: =ABS((C20-D20)/(D20)) -> 0.019145525 | F20: < 2% | G20: < 4%
A21: IV quadrante | B21: 10.545 | C21: 10 | D21: =B21/$C$15 -> 10.139423 | E21: =ABS((C21-D21)/(D21)) -> 0.013750593 | F21: < 2% | G21: < 4%
A22: centro | B22: 21.141 | C22: 20 | D22: =B22/$C$15 -> 20.327885 | E22: =ABS((C22-D22)/(D22)) -> 0.016129795 | F22: < 2% | G22: < 4%
C24: Rapporto formato | D24: Toll.
C25: =SUM(C18:C22)/SUM(D18:D22) -> 0.98491066 | D25: < 3%
A29: Uniformità di risoluzione (DDR10 – Uniformity of resolution)
A31: Tensione | B31: (kV) | C31: 50
A32: Filtrazione aggiuntiva | B32: (mmAl + mmCu) | C32: assente
A33: DFR | B33: (cm) | C33: 130
A34: Corrente x tempo | B34: mAs | C34: 2
A35: Fantoccio: | B35: ETR
A36: Griglia | B36: =Report!B24 -> Assente
A38: Distorsioni visibili: | B38: (Sì/No) | C38: No
